2014-06-24 18:44:02,825 [ERROR] django.request: Internal Server Error: /example/contact/edit/3
Traceback (most recent call last):
  File "C:\djangomerlin\lib\site-packages\django\core\handlers\base.py", line 92, in get_response
    response = middleware_method(request)
  File "C:\djangomerlin\lib\site-packages\django\middleware\common.py", line 69, in process_request
    if (not urlresolvers.is_valid_path(request.path_info, urlconf) and
  File "C:\djangomerlin\lib\site-packages\django\core\urlresolvers.py", line 551, in is_valid_path
    resolve(path, urlconf)
  File "C:\djangomerlin\lib\site-packages\django\core\urlresolvers.py", line 440, in resolve
    return get_resolver(urlconf).resolve(path)
  File "C:\djangomerlin\lib\site-packages\django\core\urlresolvers.py", line 319, in resolve
    for pattern in self.url_patterns:
  File "C:\djangomerlin\lib\site-packages\django\core\urlresolvers.py", line 347, in url_patterns
    patterns = getattr(self.urlconf_module, "urlpatterns", self.urlconf_module)
  File "C:\djangomerlin\lib\site-packages\django\core\urlresolvers.py", line 342, in urlconf_module
    self._urlconf_module = import_module(self.urlconf_name)
  File "C:\djangomerlin\lib\site-packages\django\utils\importlib.py", line 35, in import_module
    __import__(name)
  File "C:\sessionwiz_models\sessionwiz\urls.py", line 8, in <module>
    url(r'^example/', include('example.urls', namespace='example')),
  File "C:\djangomerlin\lib\site-packages\django\conf\urls\__init__.py", line 25, in include
    urlconf_module = import_module(urlconf_module)
  File "C:\djangomerlin\lib\site-packages\django\utils\importlib.py", line 35, in import_module
    __import__(name)
  File "C:\sessionwiz_models\example\urls.py", line 5, in <module>
    from example import views
  File "C:\sessionwiz_models\example\views.py", line 169
    if (self.steps.current == self.steps.last) or
                                                ^
SyntaxError: invalid syntax
2014-06-24 18:46:21,200 [ERROR] django.request: Internal Server Error: /example/contact/edit/3
Traceback (most recent call last):
  File "C:\djangomerlin\lib\site-packages\django\core\handlers\base.py", line 115, in get_response
    response = callback(request, *callback_args, **callback_kwargs)
  File "C:\sessionwiz_models\example\views.py", line 193, in edit_wizard
    return form(context=RequestContext(request), request=request)
  File "C:\djangomerlin\lib\site-packages\django\views\generic\base.py", line 68, in view
    return self.dispatch(request, *args, **kwargs)
  File "C:\djangomerlin\lib\site-packages\django\contrib\formtools\wizard\views.py", line 227, in dispatch
    response = super(WizardView, self).dispatch(request, *args, **kwargs)
  File "C:\djangomerlin\lib\site-packages\django\views\generic\base.py", line 86, in dispatch
    return handler(request, *args, **kwargs)
  File "C:\sessionwiz_models\example\views.py", line 133, in post
    return self.render_goto_step(wizard_goto_step)
AttributeError: 'ContactWizard' object has no attribute 'render_goto_step'
2014-06-24 18:49:50,591 [ERROR] django.request: Internal Server Error: /example/contact/edit/1
Traceback (most recent call last):
  File "C:\djangomerlin\lib\site-packages\django\core\handlers\base.py", line 115, in get_response
    response = callback(request, *callback_args, **callback_kwargs)
  File "C:\sessionwiz_models\example\views.py", line 193, in edit_wizard
    return form(context=RequestContext(request), request=request)
  File "C:\djangomerlin\lib\site-packages\django\views\generic\base.py", line 68, in view
    return self.dispatch(request, *args, **kwargs)
  File "C:\djangomerlin\lib\site-packages\django\contrib\formtools\wizard\views.py", line 227, in dispatch
    response = super(WizardView, self).dispatch(request, *args, **kwargs)
  File "C:\djangomerlin\lib\site-packages\django\views\generic\base.py", line 86, in dispatch
    return handler(request, *args, **kwargs)
  File "C:\sessionwiz_models\example\views.py", line 170, in post
    (self.request.POST['save_comeback_later']):
  File "C:\djangomerlin\lib\site-packages\django\utils\datastructures.py", line 295, in __getitem__
    raise MultiValueDictKeyError("Key %r not found in %r" % (key, self))
MultiValueDictKeyError: "Key 'save_comeback_later' not found in <QueryDict: {u'contact_wizard-current_step': [u'0'], u'csrfmiddlewaretoken': [u'k8unGOwAF5y1L5VjrsV3fTHMySZnYAsL'], u'0-subject': [u'test statement3a']}>"
2014-06-24 19:04:34,983 [ERROR] django.request: Internal Server Error: /example/contact/edit/4
Traceback (most recent call last):
  File "C:\djangomerlin\lib\site-packages\django\core\handlers\base.py", line 115, in get_response
    response = callback(request, *callback_args, **callback_kwargs)
  File "C:\sessionwiz_models\example\views.py", line 194, in edit_wizard
    return form(context=RequestContext(request), request=request)
  File "C:\djangomerlin\lib\site-packages\django\views\generic\base.py", line 68, in view
    return self.dispatch(request, *args, **kwargs)
  File "C:\djangomerlin\lib\site-packages\django\contrib\formtools\wizard\views.py", line 227, in dispatch
    response = super(WizardView, self).dispatch(request, *args, **kwargs)
  File "C:\djangomerlin\lib\site-packages\django\views\generic\base.py", line 86, in dispatch
    return handler(request, *args, **kwargs)
  File "C:\sessionwiz_models\example\views.py", line 133, in post
    return self.render_goto_step(wizard_goto_step)
AttributeError: 'ContactWizard' object has no attribute 'render_goto_step'
2014-06-24 19:25:47,548 [ERROR] django.request: Internal Server Error: /example/contact/edit/1
Traceback (most recent call last):
  File "C:\djangomerlin\lib\site-packages\django\core\handlers\base.py", line 115, in get_response
    response = callback(request, *callback_args, **callback_kwargs)
  File "C:\sessionwiz_models\example\views.py", line 210, in edit_wizard
    return form(context=RequestContext(request), request=request)
  File "C:\djangomerlin\lib\site-packages\django\views\generic\base.py", line 68, in view
    return self.dispatch(request, *args, **kwargs)
  File "C:\djangomerlin\lib\site-packages\django\contrib\formtools\wizard\views.py", line 227, in dispatch
    response = super(WizardView, self).dispatch(request, *args, **kwargs)
  File "C:\djangomerlin\lib\site-packages\django\views\generic\base.py", line 86, in dispatch
    return handler(request, *args, **kwargs)
  File "C:\sessionwiz_models\example\views.py", line 126, in post
    final_forms = OrderDict()
NameError: global name 'OrderDict' is not defined
2014-06-24 19:26:06,809 [ERROR] django.request: Internal Server Error: /example/contact/edit/1
Traceback (most recent call last):
  File "C:\djangomerlin\lib\site-packages\django\core\handlers\base.py", line 115, in get_response
    response = callback(request, *callback_args, **callback_kwargs)
  File "C:\sessionwiz_models\example\views.py", line 210, in edit_wizard
    return form(context=RequestContext(request), request=request)
  File "C:\djangomerlin\lib\site-packages\django\views\generic\base.py", line 68, in view
    return self.dispatch(request, *args, **kwargs)
  File "C:\djangomerlin\lib\site-packages\django\contrib\formtools\wizard\views.py", line 227, in dispatch
    response = super(WizardView, self).dispatch(request, *args, **kwargs)
  File "C:\djangomerlin\lib\site-packages\django\views\generic\base.py", line 86, in dispatch
    return handler(request, *args, **kwargs)
  File "C:\sessionwiz_models\example\views.py", line 126, in post
    final_forms = OrderDict()
NameError: global name 'OrderDict' is not defined
2014-06-24 19:26:48,709 [ERROR] django.request: Internal Server Error: /example/contact/edit/1
Traceback (most recent call last):
  File "C:\djangomerlin\lib\site-packages\django\core\handlers\base.py", line 115, in get_response
    response = callback(request, *callback_args, **callback_kwargs)
  File "C:\sessionwiz_models\example\views.py", line 210, in edit_wizard
    return form(context=RequestContext(request), request=request)
  File "C:\djangomerlin\lib\site-packages\django\views\generic\base.py", line 68, in view
    return self.dispatch(request, *args, **kwargs)
  File "C:\djangomerlin\lib\site-packages\django\contrib\formtools\wizard\views.py", line 227, in dispatch
    response = super(WizardView, self).dispatch(request, *args, **kwargs)
  File "C:\djangomerlin\lib\site-packages\django\views\generic\base.py", line 86, in dispatch
    return handler(request, *args, **kwargs)
  File "C:\sessionwiz_models\example\views.py", line 130, in post
    files=self.storage_get_step_files(form_key))
AttributeError: 'ContactWizard' object has no attribute 'storage_get_step_files'
2014-06-24 19:27:38,177 [ERROR] django.request: Internal Server Error: /example/contact/edit/1
Traceback (most recent call last):
  File "C:\djangomerlin\lib\site-packages\django\core\handlers\base.py", line 115, in get_response
    response = callback(request, *callback_args, **callback_kwargs)
  File "C:\sessionwiz_models\example\views.py", line 210, in edit_wizard
    return form(context=RequestContext(request), request=request)
  File "C:\djangomerlin\lib\site-packages\django\views\generic\base.py", line 68, in view
    return self.dispatch(request, *args, **kwargs)
  File "C:\djangomerlin\lib\site-packages\django\contrib\formtools\wizard\views.py", line 227, in dispatch
    response = super(WizardView, self).dispatch(request, *args, **kwargs)
  File "C:\djangomerlin\lib\site-packages\django\views\generic\base.py", line 86, in dispatch
    return handler(request, *args, **kwargs)
  File "C:\sessionwiz_models\example\views.py", line 129, in post
    data=super(ContactWizard, self).storage.get_step_data(form_key),
AttributeError: 'super' object has no attribute 'storage'
2014-06-24 19:28:01,398 [ERROR] django.request: Internal Server Error: /example/contact/edit/1
Traceback (most recent call last):
  File "C:\djangomerlin\lib\site-packages\django\core\handlers\base.py", line 115, in get_response
    response = callback(request, *callback_args, **callback_kwargs)
  File "C:\sessionwiz_models\example\views.py", line 210, in edit_wizard
    return form(context=RequestContext(request), request=request)
  File "C:\djangomerlin\lib\site-packages\django\views\generic\base.py", line 68, in view
    return self.dispatch(request, *args, **kwargs)
  File "C:\djangomerlin\lib\site-packages\django\contrib\formtools\wizard\views.py", line 227, in dispatch
    response = super(WizardView, self).dispatch(request, *args, **kwargs)
  File "C:\djangomerlin\lib\site-packages\django\views\generic\base.py", line 86, in dispatch
    return handler(request, *args, **kwargs)
  File "C:\sessionwiz_models\example\views.py", line 129, in post
    data=super(ContactWizard, self).storage.get_step_data(form_key),
AttributeError: 'super' object has no attribute 'storage'
2014-06-24 19:29:06,440 [ERROR] django.request: Internal Server Error: /example/contact/edit/1
Traceback (most recent call last):
  File "C:\djangomerlin\lib\site-packages\django\core\handlers\base.py", line 115, in get_response
    response = callback(request, *callback_args, **callback_kwargs)
  File "C:\sessionwiz_models\example\views.py", line 210, in edit_wizard
    return form(context=RequestContext(request), request=request)
  File "C:\djangomerlin\lib\site-packages\django\views\generic\base.py", line 68, in view
    return self.dispatch(request, *args, **kwargs)
  File "C:\djangomerlin\lib\site-packages\django\contrib\formtools\wizard\views.py", line 227, in dispatch
    response = super(WizardView, self).dispatch(request, *args, **kwargs)
  File "C:\djangomerlin\lib\site-packages\django\views\generic\base.py", line 86, in dispatch
    return handler(request, *args, **kwargs)
  File "C:\sessionwiz_models\example\views.py", line 129, in post
    data=super(ContactWizard, self).storage.get_step_data(form_key),
AttributeError: 'super' object has no attribute 'storage'
2014-06-24 19:30:24,588 [ERROR] django.request: Internal Server Error: /example/contact/edit/4
Traceback (most recent call last):
  File "C:\djangomerlin\lib\site-packages\django\core\handlers\base.py", line 115, in get_response
    response = callback(request, *callback_args, **callback_kwargs)
  File "C:\sessionwiz_models\example\views.py", line 210, in edit_wizard
    return form(context=RequestContext(request), request=request)
  File "C:\djangomerlin\lib\site-packages\django\views\generic\base.py", line 68, in view
    return self.dispatch(request, *args, **kwargs)
  File "C:\djangomerlin\lib\site-packages\django\contrib\formtools\wizard\views.py", line 227, in dispatch
    response = super(WizardView, self).dispatch(request, *args, **kwargs)
  File "C:\djangomerlin\lib\site-packages\django\views\generic\base.py", line 86, in dispatch
    return handler(request, *args, **kwargs)
  File "C:\sessionwiz_models\example\views.py", line 129, in post
    data=super(ContactWizard, self).storage.get_step_data(form_key),
AttributeError: 'super' object has no attribute 'storage'
2014-06-24 19:32:32,505 [ERROR] django.request: Internal Server Error: /example/contact/edit/4
Traceback (most recent call last):
  File "C:\djangomerlin\lib\site-packages\django\core\handlers\base.py", line 115, in get_response
    response = callback(request, *callback_args, **callback_kwargs)
  File "C:\sessionwiz_models\example\views.py", line 211, in edit_wizard
    return form(context=RequestContext(request), request=request)
  File "C:\djangomerlin\lib\site-packages\django\views\generic\base.py", line 68, in view
    return self.dispatch(request, *args, **kwargs)
  File "C:\djangomerlin\lib\site-packages\django\contrib\formtools\wizard\views.py", line 227, in dispatch
    response = super(WizardView, self).dispatch(request, *args, **kwargs)
  File "C:\djangomerlin\lib\site-packages\django\views\generic\base.py", line 86, in dispatch
    return handler(request, *args, **kwargs)
  File "C:\sessionwiz_models\example\views.py", line 130, in post
    data=super(ContactWizard, self).storage.get_step_data(form_key),
AttributeError: 'super' object has no attribute 'storage'
2014-06-24 19:33:02,846 [ERROR] django.request: Internal Server Error: /example/contact/edit/4
Traceback (most recent call last):
  File "C:\djangomerlin\lib\site-packages\django\core\handlers\base.py", line 115, in get_response
    response = callback(request, *callback_args, **callback_kwargs)
  File "C:\sessionwiz_models\example\views.py", line 212, in edit_wizard
    return form(context=RequestContext(request), request=request)
  File "C:\djangomerlin\lib\site-packages\django\views\generic\base.py", line 68, in view
    return self.dispatch(request, *args, **kwargs)
  File "C:\djangomerlin\lib\site-packages\django\contrib\formtools\wizard\views.py", line 227, in dispatch
    response = super(WizardView, self).dispatch(request, *args, **kwargs)
  File "C:\djangomerlin\lib\site-packages\django\views\generic\base.py", line 86, in dispatch
    return handler(request, *args, **kwargs)
  File "C:\sessionwiz_models\example\views.py", line 131, in post
    data=super(ContactWizard, self).storage.get_step_data(form_key),
AttributeError: 'super' object has no attribute 'storage'
2014-06-24 19:34:33,986 [ERROR] django.request: Internal Server Error: /example/contact/edit/4
Traceback (most recent call last):
  File "C:\djangomerlin\lib\site-packages\django\core\handlers\base.py", line 115, in get_response
    response = callback(request, *callback_args, **callback_kwargs)
  File "C:\sessionwiz_models\example\views.py", line 213, in edit_wizard
    return form(context=RequestContext(request), request=request)
  File "C:\djangomerlin\lib\site-packages\django\views\generic\base.py", line 68, in view
    return self.dispatch(request, *args, **kwargs)
  File "C:\djangomerlin\lib\site-packages\django\contrib\formtools\wizard\views.py", line 227, in dispatch
    response = super(WizardView, self).dispatch(request, *args, **kwargs)
  File "C:\djangomerlin\lib\site-packages\django\views\generic\base.py", line 86, in dispatch
    return handler(request, *args, **kwargs)
  File "C:\sessionwiz_models\example\views.py", line 130, in post
    logr.debug("list of forms: " + super(self.get_form_list()))
TypeError: must be type, not SortedDict
2014-06-24 19:35:26,983 [ERROR] django.request: Internal Server Error: /example/contact/edit/4
Traceback (most recent call last):
  File "C:\djangomerlin\lib\site-packages\django\core\handlers\base.py", line 115, in get_response
    response = callback(request, *callback_args, **callback_kwargs)
  File "C:\sessionwiz_models\example\views.py", line 213, in edit_wizard
    return form(context=RequestContext(request), request=request)
  File "C:\djangomerlin\lib\site-packages\django\views\generic\base.py", line 68, in view
    return self.dispatch(request, *args, **kwargs)
  File "C:\djangomerlin\lib\site-packages\django\contrib\formtools\wizard\views.py", line 227, in dispatch
    response = super(WizardView, self).dispatch(request, *args, **kwargs)
  File "C:\djangomerlin\lib\site-packages\django\views\generic\base.py", line 86, in dispatch
    return handler(request, *args, **kwargs)
  File "C:\sessionwiz_models\example\views.py", line 132, in post
    data=super(ContactWizard, self).storage.get_step_data(form_key),
AttributeError: 'super' object has no attribute 'storage'
2014-06-24 21:05:46,203 [ERROR] django.request: Internal Server Error: /example/contact/edit/4
Traceback (most recent call last):
  File "C:\djangomerlin\lib\site-packages\django\core\handlers\base.py", line 92, in get_response
    response = middleware_method(request)
  File "C:\djangomerlin\lib\site-packages\django\middleware\common.py", line 69, in process_request
    if (not urlresolvers.is_valid_path(request.path_info, urlconf) and
  File "C:\djangomerlin\lib\site-packages\django\core\urlresolvers.py", line 551, in is_valid_path
    resolve(path, urlconf)
  File "C:\djangomerlin\lib\site-packages\django\core\urlresolvers.py", line 440, in resolve
    return get_resolver(urlconf).resolve(path)
  File "C:\djangomerlin\lib\site-packages\django\core\urlresolvers.py", line 319, in resolve
    for pattern in self.url_patterns:
  File "C:\djangomerlin\lib\site-packages\django\core\urlresolvers.py", line 347, in url_patterns
    patterns = getattr(self.urlconf_module, "urlpatterns", self.urlconf_module)
  File "C:\djangomerlin\lib\site-packages\django\core\urlresolvers.py", line 342, in urlconf_module
    self._urlconf_module = import_module(self.urlconf_name)
  File "C:\djangomerlin\lib\site-packages\django\utils\importlib.py", line 35, in import_module
    __import__(name)
  File "C:\sessionwiz_models\sessionwiz\urls.py", line 8, in <module>
    url(r'^example/', include('example.urls', namespace='example')),
  File "C:\djangomerlin\lib\site-packages\django\conf\urls\__init__.py", line 25, in include
    urlconf_module = import_module(urlconf_module)
  File "C:\djangomerlin\lib\site-packages\django\utils\importlib.py", line 35, in import_module
    __import__(name)
  File "C:\sessionwiz_models\example\urls.py", line 5, in <module>
    from example import views
  File "C:\sessionwiz_models\example\views.py", line 144
    logr.debug("value is TRUE")
                              ^
IndentationError: unindent does not match any outer indentation level
2014-06-24 22:08:37,124 [ERROR] django.request: Internal Server Error: /example/contact/edit/4
Traceback (most recent call last):
  File "C:\djangomerlin\lib\site-packages\django\core\handlers\base.py", line 115, in get_response
    response = callback(request, *callback_args, **callback_kwargs)
  File "C:\sessionwiz_models\example\views.py", line 215, in edit_wizard
    return form(context=RequestContext(request), request=request)
  File "C:\djangomerlin\lib\site-packages\django\views\generic\base.py", line 68, in view
    return self.dispatch(request, *args, **kwargs)
  File "C:\djangomerlin\lib\site-packages\django\contrib\formtools\wizard\views.py", line 227, in dispatch
    response = super(WizardView, self).dispatch(request, *args, **kwargs)
  File "C:\djangomerlin\lib\site-packages\django\views\generic\base.py", line 86, in dispatch
    return handler(request, *args, **kwargs)
  File "C:\sessionwiz_models\example\views.py", line 156, in post
    return super(ContactWizard, self).render_goto_step(goto_step=wizard_goto_step, **kwargs)
AttributeError: 'super' object has no attribute 'render_goto_step'
2014-06-24 22:09:24,374 [ERROR] django.request: Internal Server Error: /example/contact/edit/4
Traceback (most recent call last):
  File "C:\djangomerlin\lib\site-packages\django\core\handlers\base.py", line 115, in get_response
    response = callback(request, *callback_args, **callback_kwargs)
  File "C:\sessionwiz_models\example\views.py", line 215, in edit_wizard
    return form(context=RequestContext(request), request=request)
  File "C:\djangomerlin\lib\site-packages\django\views\generic\base.py", line 68, in view
    return self.dispatch(request, *args, **kwargs)
  File "C:\djangomerlin\lib\site-packages\django\contrib\formtools\wizard\views.py", line 227, in dispatch
    response = super(WizardView, self).dispatch(request, *args, **kwargs)
  File "C:\djangomerlin\lib\site-packages\django\views\generic\base.py", line 86, in dispatch
    return handler(request, *args, **kwargs)
  File "C:\sessionwiz_models\example\views.py", line 156, in post
    return self.render_goto_step(goto_step=wizard_goto_step, **kwargs)
AttributeError: 'ContactWizard' object has no attribute 'render_goto_step'
2014-06-24 22:20:42,982 [ERROR] django.request: Internal Server Error: /example/contact/edit/4
Traceback (most recent call last):
  File "C:\djangomerlin\lib\site-packages\django\core\handlers\base.py", line 115, in get_response
    response = callback(request, *callback_args, **callback_kwargs)
  File "C:\sessionwiz_models\example\views.py", line 221, in edit_wizard
    return form(context=RequestContext(request), request=request)
  File "C:\djangomerlin\lib\site-packages\django\views\generic\base.py", line 68, in view
    return self.dispatch(request, *args, **kwargs)
  File "C:\djangomerlin\lib\site-packages\django\contrib\formtools\wizard\views.py", line 227, in dispatch
    response = super(WizardView, self).dispatch(request, *args, **kwargs)
  File "C:\djangomerlin\lib\site-packages\django\views\generic\base.py", line 86, in dispatch
    return handler(request, *args, **kwargs)
  File "C:\djangomerlin\lib\site-packages\django\contrib\formtools\wizard\views.py", line 245, in get
    return self.render(self.get_form())
  File "C:\djangomerlin\lib\site-packages\django\contrib\formtools\wizard\views.py", line 389, in get_form
    'initial': self.get_form_initial(step),
  File "C:\sessionwiz_models\example\views.py", line 48, in get_form_initial
    logr.debug("initial dat for step: " + str(step) + ": " + self.kwargs)
TypeError: cannot concatenate 'str' and 'dict' objects
2014-06-24 22:35:46,308 [ERROR] django.request: Internal Server Error: /example/contact/edit/4
Traceback (most recent call last):
  File "C:\djangomerlin\lib\site-packages\django\core\handlers\base.py", line 92, in get_response
    response = middleware_method(request)
  File "C:\djangomerlin\lib\site-packages\django\middleware\common.py", line 69, in process_request
    if (not urlresolvers.is_valid_path(request.path_info, urlconf) and
  File "C:\djangomerlin\lib\site-packages\django\core\urlresolvers.py", line 551, in is_valid_path
    resolve(path, urlconf)
  File "C:\djangomerlin\lib\site-packages\django\core\urlresolvers.py", line 440, in resolve
    return get_resolver(urlconf).resolve(path)
  File "C:\djangomerlin\lib\site-packages\django\core\urlresolvers.py", line 319, in resolve
    for pattern in self.url_patterns:
  File "C:\djangomerlin\lib\site-packages\django\core\urlresolvers.py", line 347, in url_patterns
    patterns = getattr(self.urlconf_module, "urlpatterns", self.urlconf_module)
  File "C:\djangomerlin\lib\site-packages\django\core\urlresolvers.py", line 342, in urlconf_module
    self._urlconf_module = import_module(self.urlconf_name)
  File "C:\djangomerlin\lib\site-packages\django\utils\importlib.py", line 35, in import_module
    __import__(name)
  File "C:\sessionwiz_models\sessionwiz\urls.py", line 8, in <module>
    url(r'^example/', include('example.urls', namespace='example')),
  File "C:\djangomerlin\lib\site-packages\django\conf\urls\__init__.py", line 25, in include
    urlconf_module = import_module(urlconf_module)
  File "C:\djangomerlin\lib\site-packages\django\utils\importlib.py", line 35, in import_module
    __import__(name)
  File "C:\sessionwiz_models\example\urls.py", line 25
    url(r'^contact/submit/$', views.submit_wizard, name='submit_confirm'),
      ^
SyntaxError: invalid syntax
2014-06-24 22:37:25,693 [ERROR] django.request: Internal Server Error: /example/contact/edit/6
Traceback (most recent call last):
  File "C:\djangomerlin\lib\site-packages\django\core\handlers\base.py", line 115, in get_response
    response = callback(request, *callback_args, **callback_kwargs)
  File "C:\djangomerlin\lib\site-packages\django\views\generic\base.py", line 68, in view
    return self.dispatch(request, *args, **kwargs)
  File "C:\djangomerlin\lib\site-packages\django\contrib\formtools\wizard\views.py", line 227, in dispatch
    response = super(WizardView, self).dispatch(request, *args, **kwargs)
  File "C:\djangomerlin\lib\site-packages\django\views\generic\base.py", line 86, in dispatch
    return handler(request, *args, **kwargs)
  File "C:\djangomerlin\lib\site-packages\django\contrib\formtools\wizard\views.py", line 245, in get
    return self.render(self.get_form())
  File "C:\djangomerlin\lib\site-packages\django\contrib\formtools\wizard\views.py", line 389, in get_form
    'initial': self.get_form_initial(step),
  File "C:\sessionwiz_models\example\views.py", line 48, in get_form_initial
    logr.debug("statement_id is: " + str(request.session['statement_id']))
NameError: global name 'request' is not defined
2014-06-24 22:37:40,944 [ERROR] django.request: Internal Server Error: /example/contact/edit/6
Traceback (most recent call last):
  File "C:\djangomerlin\lib\site-packages\django\core\handlers\base.py", line 115, in get_response
    response = callback(request, *callback_args, **callback_kwargs)
  File "C:\djangomerlin\lib\site-packages\django\views\generic\base.py", line 68, in view
    return self.dispatch(request, *args, **kwargs)
  File "C:\djangomerlin\lib\site-packages\django\contrib\formtools\wizard\views.py", line 227, in dispatch
    response = super(WizardView, self).dispatch(request, *args, **kwargs)
  File "C:\djangomerlin\lib\site-packages\django\views\generic\base.py", line 86, in dispatch
    return handler(request, *args, **kwargs)
  File "C:\djangomerlin\lib\site-packages\django\contrib\formtools\wizard\views.py", line 245, in get
    return self.render(self.get_form())
  File "C:\djangomerlin\lib\site-packages\django\contrib\formtools\wizard\views.py", line 389, in get_form
    'initial': self.get_form_initial(step),
  File "C:\sessionwiz_models\example\views.py", line 48, in get_form_initial
    logr.debug("statement_id is: " + str(self.request.session['statement_id']))
  File "C:\djangomerlin\lib\site-packages\django\contrib\sessions\backends\base.py", line 44, in __getitem__
    return self._session[key]
KeyError: 'statement_id'
2014-06-24 22:38:29,392 [ERROR] django.request: Internal Server Error: /example/contact/edit/6
Traceback (most recent call last):
  File "C:\djangomerlin\lib\site-packages\django\core\handlers\base.py", line 115, in get_response
    response = callback(request, *callback_args, **callback_kwargs)
  File "C:\djangomerlin\lib\site-packages\django\views\generic\base.py", line 68, in view
    return self.dispatch(request, *args, **kwargs)
  File "C:\djangomerlin\lib\site-packages\django\contrib\formtools\wizard\views.py", line 227, in dispatch
    response = super(WizardView, self).dispatch(request, *args, **kwargs)
  File "C:\djangomerlin\lib\site-packages\django\views\generic\base.py", line 86, in dispatch
    return handler(request, *args, **kwargs)
  File "C:\djangomerlin\lib\site-packages\django\contrib\formtools\wizard\views.py", line 245, in get
    return self.render(self.get_form())
  File "C:\djangomerlin\lib\site-packages\django\contrib\formtools\wizard\views.py", line 389, in get_form
    'initial': self.get_form_initial(step),
  File "C:\sessionwiz_models\example\views.py", line 48, in get_form_initial
    logr.debug("statement_id is: " + self.request.session)
TypeError: cannot concatenate 'str' and 'SessionStore' objects
2014-06-24 22:39:56,022 [ERROR] django.request: Internal Server Error: /example/contact/edit/6
Traceback (most recent call last):
  File "C:\djangomerlin\lib\site-packages\django\core\handlers\base.py", line 115, in get_response
    response = callback(request, *callback_args, **callback_kwargs)
  File "C:\djangomerlin\lib\site-packages\django\views\generic\base.py", line 68, in view
    return self.dispatch(request, *args, **kwargs)
  File "C:\djangomerlin\lib\site-packages\django\contrib\formtools\wizard\views.py", line 227, in dispatch
    response = super(WizardView, self).dispatch(request, *args, **kwargs)
  File "C:\djangomerlin\lib\site-packages\django\views\generic\base.py", line 86, in dispatch
    return handler(request, *args, **kwargs)
  File "C:\djangomerlin\lib\site-packages\django\contrib\formtools\wizard\views.py", line 245, in get
    return self.render(self.get_form())
  File "C:\djangomerlin\lib\site-packages\django\contrib\formtools\wizard\views.py", line 389, in get_form
    'initial': self.get_form_initial(step),
  File "C:\sessionwiz_models\example\views.py", line 49, in get_form_initial
    logr.debug(self.request.session['statement_id'])
  File "C:\djangomerlin\lib\site-packages\django\contrib\sessions\backends\base.py", line 44, in __getitem__
    return self._session[key]
KeyError: 'statement_id'
2014-06-24 23:17:42,493 [ERROR] django.request: Internal Server Error: /example/contact/edit/6
Traceback (most recent call last):
  File "C:\djangomerlin\lib\site-packages\django\core\handlers\base.py", line 115, in get_response
    response = callback(request, *callback_args, **callback_kwargs)
  File "C:\djangomerlin\lib\site-packages\django\views\generic\base.py", line 68, in view
    return self.dispatch(request, *args, **kwargs)
  File "C:\djangomerlin\lib\site-packages\django\contrib\formtools\wizard\views.py", line 227, in dispatch
    response = super(WizardView, self).dispatch(request, *args, **kwargs)
  File "C:\djangomerlin\lib\site-packages\django\views\generic\base.py", line 86, in dispatch
    return handler(request, *args, **kwargs)
  File "C:\djangomerlin\lib\site-packages\django\contrib\formtools\wizard\views.py", line 245, in get
    return self.render(self.get_form())
  File "C:\djangomerlin\lib\site-packages\django\contrib\formtools\wizard\views.py", line 389, in get_form
    'initial': self.get_form_initial(step),
  File "C:\sessionwiz_models\example\views.py", line 62, in get_form_initial
    logr.debug(eachform.fields)
AttributeError: type object 'ContactForm1' has no attribute 'fields'
2014-06-24 23:20:49,700 [ERROR] django.request: Internal Server Error: /example/contact/edit/6
Traceback (most recent call last):
  File "C:\djangomerlin\lib\site-packages\django\core\handlers\base.py", line 115, in get_response
    response = callback(request, *callback_args, **callback_kwargs)
  File "C:\djangomerlin\lib\site-packages\django\views\generic\base.py", line 68, in view
    return self.dispatch(request, *args, **kwargs)
  File "C:\djangomerlin\lib\site-packages\django\contrib\formtools\wizard\views.py", line 227, in dispatch
    response = super(WizardView, self).dispatch(request, *args, **kwargs)
  File "C:\djangomerlin\lib\site-packages\django\views\generic\base.py", line 86, in dispatch
    return handler(request, *args, **kwargs)
  File "C:\djangomerlin\lib\site-packages\django\contrib\formtools\wizard\views.py", line 245, in get
    return self.render(self.get_form())
  File "C:\djangomerlin\lib\site-packages\django\contrib\formtools\wizard\views.py", line 389, in get_form
    'initial': self.get_form_initial(step),
  File "C:\sessionwiz_models\example\views.py", line 62, in get_form_initial
    for eachfield in eachform:
TypeError: 'ModelFormMetaclass' object is not iterable
2014-06-24 23:21:02,453 [ERROR] django.request: Internal Server Error: /example/contact/edit/6
Traceback (most recent call last):
  File "C:\djangomerlin\lib\site-packages\django\core\handlers\base.py", line 115, in get_response
    response = callback(request, *callback_args, **callback_kwargs)
  File "C:\djangomerlin\lib\site-packages\django\views\generic\base.py", line 68, in view
    return self.dispatch(request, *args, **kwargs)
  File "C:\djangomerlin\lib\site-packages\django\contrib\formtools\wizard\views.py", line 227, in dispatch
    response = super(WizardView, self).dispatch(request, *args, **kwargs)
  File "C:\djangomerlin\lib\site-packages\django\views\generic\base.py", line 86, in dispatch
    return handler(request, *args, **kwargs)
  File "C:\djangomerlin\lib\site-packages\django\contrib\formtools\wizard\views.py", line 245, in get
    return self.render(self.get_form())
  File "C:\djangomerlin\lib\site-packages\django\contrib\formtools\wizard\views.py", line 389, in get_form
    'initial': self.get_form_initial(step),
  File "C:\sessionwiz_models\example\views.py", line 62, in get_form_initial
    for eachfield in eachform.fields:
TypeError: 'ModelFormMetaclass' object is not iterable
2014-06-24 23:29:06,986 [ERROR] django.request: Internal Server Error: /example/contact/edit/6
Traceback (most recent call last):
  File "C:\djangomerlin\lib\site-packages\django\core\handlers\base.py", line 115, in get_response
    response = callback(request, *callback_args, **callback_kwargs)
  File "C:\djangomerlin\lib\site-packages\django\views\generic\base.py", line 68, in view
    return self.dispatch(request, *args, **kwargs)
  File "C:\djangomerlin\lib\site-packages\django\contrib\formtools\wizard\views.py", line 227, in dispatch
    response = super(WizardView, self).dispatch(request, *args, **kwargs)
  File "C:\djangomerlin\lib\site-packages\django\views\generic\base.py", line 86, in dispatch
    return handler(request, *args, **kwargs)
  File "C:\djangomerlin\lib\site-packages\django\contrib\formtools\wizard\views.py", line 245, in get
    return self.render(self.get_form())
  File "C:\djangomerlin\lib\site-packages\django\contrib\formtools\wizard\views.py", line 389, in get_form
    'initial': self.get_form_initial(step),
  File "C:\sessionwiz_models\example\views.py", line 62, in get_form_initial
    logr.debug(eachform.fields)
AttributeError: type object 'ContactForm1' has no attribute 'fields'
2014-06-24 23:29:19,601 [ERROR] django.request: Internal Server Error: /example/contact/edit/6
Traceback (most recent call last):
  File "C:\djangomerlin\lib\site-packages\django\core\handlers\base.py", line 115, in get_response
    response = callback(request, *callback_args, **callback_kwargs)
  File "C:\djangomerlin\lib\site-packages\django\views\generic\base.py", line 68, in view
    return self.dispatch(request, *args, **kwargs)
  File "C:\djangomerlin\lib\site-packages\django\contrib\formtools\wizard\views.py", line 227, in dispatch
    response = super(WizardView, self).dispatch(request, *args, **kwargs)
  File "C:\djangomerlin\lib\site-packages\django\views\generic\base.py", line 86, in dispatch
    return handler(request, *args, **kwargs)
  File "C:\djangomerlin\lib\site-packages\django\contrib\formtools\wizard\views.py", line 245, in get
    return self.render(self.get_form())
  File "C:\djangomerlin\lib\site-packages\django\contrib\formtools\wizard\views.py", line 389, in get_form
    'initial': self.get_form_initial(step),
  File "C:\sessionwiz_models\example\views.py", line 62, in get_form_initial
    logr.debug(eachform.fields())
AttributeError: type object 'ContactForm1' has no attribute 'fields'
2014-06-24 23:29:48,746 [ERROR] django.request: Internal Server Error: /example/contact/edit/6
Traceback (most recent call last):
  File "C:\djangomerlin\lib\site-packages\django\core\handlers\base.py", line 115, in get_response
    response = callback(request, *callback_args, **callback_kwargs)
  File "C:\djangomerlin\lib\site-packages\django\views\generic\base.py", line 68, in view
    return self.dispatch(request, *args, **kwargs)
  File "C:\djangomerlin\lib\site-packages\django\contrib\formtools\wizard\views.py", line 227, in dispatch
    response = super(WizardView, self).dispatch(request, *args, **kwargs)
  File "C:\djangomerlin\lib\site-packages\django\views\generic\base.py", line 86, in dispatch
    return handler(request, *args, **kwargs)
  File "C:\djangomerlin\lib\site-packages\django\contrib\formtools\wizard\views.py", line 245, in get
    return self.render(self.get_form())
  File "C:\djangomerlin\lib\site-packages\django\contrib\formtools\wizard\views.py", line 389, in get_form
    'initial': self.get_form_initial(step),
  File "C:\sessionwiz_models\example\views.py", line 62, in get_form_initial
    logr.debug(ContactForm1.fields())
AttributeError: type object 'ContactForm1' has no attribute 'fields'
2014-06-24 23:30:05,124 [ERROR] django.request: Internal Server Error: /example/contact/edit/6
Traceback (most recent call last):
  File "C:\djangomerlin\lib\site-packages\django\core\handlers\base.py", line 115, in get_response
    response = callback(request, *callback_args, **callback_kwargs)
  File "C:\djangomerlin\lib\site-packages\django\views\generic\base.py", line 68, in view
    return self.dispatch(request, *args, **kwargs)
  File "C:\djangomerlin\lib\site-packages\django\contrib\formtools\wizard\views.py", line 227, in dispatch
    response = super(WizardView, self).dispatch(request, *args, **kwargs)
  File "C:\djangomerlin\lib\site-packages\django\views\generic\base.py", line 86, in dispatch
    return handler(request, *args, **kwargs)
  File "C:\djangomerlin\lib\site-packages\django\contrib\formtools\wizard\views.py", line 245, in get
    return self.render(self.get_form())
  File "C:\djangomerlin\lib\site-packages\django\contrib\formtools\wizard\views.py", line 389, in get_form
    'initial': self.get_form_initial(step),
  File "C:\sessionwiz_models\example\views.py", line 62, in get_form_initial
    logr.debug(ContactForm1.fields.count)
AttributeError: type object 'ContactForm1' has no attribute 'fields'
2014-06-24 23:47:09,203 [ERROR] django.request: Internal Server Error: /example/contact/
Traceback (most recent call last):
  File "C:\djangomerlin\lib\site-packages\django\core\handlers\base.py", line 103, in get_response
    resolver_match = resolver.resolve(request.path_info)
  File "C:\djangomerlin\lib\site-packages\django\core\urlresolvers.py", line 319, in resolve
    for pattern in self.url_patterns:
  File "C:\djangomerlin\lib\site-packages\django\core\urlresolvers.py", line 347, in url_patterns
    patterns = getattr(self.urlconf_module, "urlpatterns", self.urlconf_module)
  File "C:\djangomerlin\lib\site-packages\django\core\urlresolvers.py", line 342, in urlconf_module
    self._urlconf_module = import_module(self.urlconf_name)
  File "C:\djangomerlin\lib\site-packages\django\utils\importlib.py", line 35, in import_module
    __import__(name)
  File "C:\sessionwiz_models\sessionwiz\urls.py", line 8, in <module>
    url(r'^example/', include('example.urls', namespace='example')),
  File "C:\djangomerlin\lib\site-packages\django\conf\urls\__init__.py", line 25, in include
    urlconf_module = import_module(urlconf_module)
  File "C:\djangomerlin\lib\site-packages\django\utils\importlib.py", line 35, in import_module
    __import__(name)
  File "C:\sessionwiz_models\example\urls.py", line 5, in <module>
    from example import views
  File "C:\sessionwiz_models\example\views.py", line 50, in <module>
    class ContactWizard(SessionWizardView):
  File "C:\sessionwiz_models\example\views.py", line 54, in ContactWizard
    logr.debug("initial dat for step: " + str(step) + ": " + str(self.kwargs['statement_id']))
NameError: name 'step' is not defined
2014-06-24 23:57:53,352 [ERROR] django.request: Internal Server Error: /example/contact/edit/1
Traceback (most recent call last):
  File "C:\djangomerlin\lib\site-packages\django\core\handlers\base.py", line 92, in get_response
    response = middleware_method(request)
  File "C:\djangomerlin\lib\site-packages\django\middleware\common.py", line 69, in process_request
    if (not urlresolvers.is_valid_path(request.path_info, urlconf) and
  File "C:\djangomerlin\lib\site-packages\django\core\urlresolvers.py", line 551, in is_valid_path
    resolve(path, urlconf)
  File "C:\djangomerlin\lib\site-packages\django\core\urlresolvers.py", line 440, in resolve
    return get_resolver(urlconf).resolve(path)
  File "C:\djangomerlin\lib\site-packages\django\core\urlresolvers.py", line 319, in resolve
    for pattern in self.url_patterns:
  File "C:\djangomerlin\lib\site-packages\django\core\urlresolvers.py", line 347, in url_patterns
    patterns = getattr(self.urlconf_module, "urlpatterns", self.urlconf_module)
  File "C:\djangomerlin\lib\site-packages\django\core\urlresolvers.py", line 342, in urlconf_module
    self._urlconf_module = import_module(self.urlconf_name)
  File "C:\djangomerlin\lib\site-packages\django\utils\importlib.py", line 35, in import_module
    __import__(name)
  File "C:\sessionwiz_models\sessionwiz\urls.py", line 8, in <module>
    url(r'^example/', include('example.urls', namespace='example')),
  File "C:\djangomerlin\lib\site-packages\django\conf\urls\__init__.py", line 25, in include
    urlconf_module = import_module(urlconf_module)
  File "C:\djangomerlin\lib\site-packages\django\utils\importlib.py", line 35, in import_module
    __import__(name)
  File "C:\sessionwiz_models\example\urls.py", line 17, in <module>
    ContactWizard.as_view(formslist),
  File "C:\djangomerlin\lib\site-packages\django\contrib\formtools\wizard\views.py", line 119, in as_view
    initkwargs = cls.get_initkwargs(*args, **kwargs)
TypeError: unbound method get_initkwargs() must be called with ContactWizard instance as first argument (got list instance instead)
2014-06-25 00:06:00,467 [ERROR] django.request: Internal Server Error: /example/contact/edit/1
Traceback (most recent call last):
  File "C:\djangomerlin\lib\site-packages\django\core\handlers\base.py", line 92, in get_response
    response = middleware_method(request)
  File "C:\djangomerlin\lib\site-packages\django\middleware\common.py", line 69, in process_request
    if (not urlresolvers.is_valid_path(request.path_info, urlconf) and
  File "C:\djangomerlin\lib\site-packages\django\core\urlresolvers.py", line 551, in is_valid_path
    resolve(path, urlconf)
  File "C:\djangomerlin\lib\site-packages\django\core\urlresolvers.py", line 440, in resolve
    return get_resolver(urlconf).resolve(path)
  File "C:\djangomerlin\lib\site-packages\django\core\urlresolvers.py", line 319, in resolve
    for pattern in self.url_patterns:
  File "C:\djangomerlin\lib\site-packages\django\core\urlresolvers.py", line 347, in url_patterns
    patterns = getattr(self.urlconf_module, "urlpatterns", self.urlconf_module)
  File "C:\djangomerlin\lib\site-packages\django\core\urlresolvers.py", line 342, in urlconf_module
    self._urlconf_module = import_module(self.urlconf_name)
  File "C:\djangomerlin\lib\site-packages\django\utils\importlib.py", line 35, in import_module
    __import__(name)
  File "C:\sessionwiz_models\sessionwiz\urls.py", line 8, in <module>
    url(r'^example/', include('example.urls', namespace='example')),
  File "C:\djangomerlin\lib\site-packages\django\conf\urls\__init__.py", line 25, in include
    urlconf_module = import_module(urlconf_module)
  File "C:\djangomerlin\lib\site-packages\django\utils\importlib.py", line 35, in import_module
    __import__(name)
  File "C:\sessionwiz_models\example\urls.py", line 17, in <module>
    ContactWizard.as_view(formslist),
  File "C:\djangomerlin\lib\site-packages\django\contrib\formtools\wizard\views.py", line 119, in as_view
    initkwargs = cls.get_initkwargs(*args, **kwargs)
TypeError: unbound method get_initkwargs() must be called with ContactWizard instance as first argument (got list instance instead)
2014-06-25 00:09:35,494 [ERROR] django.request: Internal Server Error: /example/contact/edit/1
Traceback (most recent call last):
  File "C:\djangomerlin\lib\site-packages\django\core\handlers\base.py", line 92, in get_response
    response = middleware_method(request)
  File "C:\djangomerlin\lib\site-packages\django\middleware\common.py", line 69, in process_request
    if (not urlresolvers.is_valid_path(request.path_info, urlconf) and
  File "C:\djangomerlin\lib\site-packages\django\core\urlresolvers.py", line 551, in is_valid_path
    resolve(path, urlconf)
  File "C:\djangomerlin\lib\site-packages\django\core\urlresolvers.py", line 440, in resolve
    return get_resolver(urlconf).resolve(path)
  File "C:\djangomerlin\lib\site-packages\django\core\urlresolvers.py", line 319, in resolve
    for pattern in self.url_patterns:
  File "C:\djangomerlin\lib\site-packages\django\core\urlresolvers.py", line 347, in url_patterns
    patterns = getattr(self.urlconf_module, "urlpatterns", self.urlconf_module)
  File "C:\djangomerlin\lib\site-packages\django\core\urlresolvers.py", line 342, in urlconf_module
    self._urlconf_module = import_module(self.urlconf_name)
  File "C:\djangomerlin\lib\site-packages\django\utils\importlib.py", line 35, in import_module
    __import__(name)
  File "C:\sessionwiz_models\sessionwiz\urls.py", line 8, in <module>
    url(r'^example/', include('example.urls', namespace='example')),
  File "C:\djangomerlin\lib\site-packages\django\conf\urls\__init__.py", line 25, in include
    urlconf_module = import_module(urlconf_module)
  File "C:\djangomerlin\lib\site-packages\django\utils\importlib.py", line 35, in import_module
    __import__(name)
  File "C:\sessionwiz_models\example\urls.py", line 17, in <module>
    ContactWizard.as_view(formslist),
  File "C:\djangomerlin\lib\site-packages\django\contrib\formtools\wizard\views.py", line 119, in as_view
    initkwargs = cls.get_initkwargs(*args, **kwargs)
TypeError: unbound method get_initkwargs() must be called with ContactWizard instance as first argument (got list instance instead)
2014-06-25 00:11:18,671 [ERROR] django.request: Internal Server Error: /example/contact/edit/1
Traceback (most recent call last):
  File "C:\djangomerlin\lib\site-packages\django\core\handlers\base.py", line 92, in get_response
    response = middleware_method(request)
  File "C:\djangomerlin\lib\site-packages\django\middleware\common.py", line 69, in process_request
    if (not urlresolvers.is_valid_path(request.path_info, urlconf) and
  File "C:\djangomerlin\lib\site-packages\django\core\urlresolvers.py", line 551, in is_valid_path
    resolve(path, urlconf)
  File "C:\djangomerlin\lib\site-packages\django\core\urlresolvers.py", line 440, in resolve
    return get_resolver(urlconf).resolve(path)
  File "C:\djangomerlin\lib\site-packages\django\core\urlresolvers.py", line 319, in resolve
    for pattern in self.url_patterns:
  File "C:\djangomerlin\lib\site-packages\django\core\urlresolvers.py", line 347, in url_patterns
    patterns = getattr(self.urlconf_module, "urlpatterns", self.urlconf_module)
  File "C:\djangomerlin\lib\site-packages\django\core\urlresolvers.py", line 342, in urlconf_module
    self._urlconf_module = import_module(self.urlconf_name)
  File "C:\djangomerlin\lib\site-packages\django\utils\importlib.py", line 35, in import_module
    __import__(name)
  File "C:\sessionwiz_models\sessionwiz\urls.py", line 8, in <module>
    url(r'^example/', include('example.urls', namespace='example')),
  File "C:\djangomerlin\lib\site-packages\django\conf\urls\__init__.py", line 25, in include
    urlconf_module = import_module(urlconf_module)
  File "C:\djangomerlin\lib\site-packages\django\utils\importlib.py", line 35, in import_module
    __import__(name)
  File "C:\sessionwiz_models\example\urls.py", line 17, in <module>
    ContactWizard.as_view(formslist),
  File "C:\djangomerlin\lib\site-packages\django\contrib\formtools\wizard\views.py", line 119, in as_view
    initkwargs = cls.get_initkwargs(*args, **kwargs)
TypeError: unbound method get_initkwargs() must be called with ContactWizard instance as first argument (got list instance instead)
2014-06-25 00:36:33,976 [ERROR] django.request: Internal Server Error: /example/contact/edit/2
Traceback (most recent call last):
  File "C:\djangomerlin\lib\site-packages\django\core\handlers\base.py", line 115, in get_response
    response = callback(request, *callback_args, **callback_kwargs)
  File "C:\sessionwiz_models\example\views.py", line 171, in edit_wizard
    'sender': given_context['sender'],
NameError: global name 'given_context' is not defined
2014-06-25 01:28:55,055 [ERROR] django.request: Internal Server Error: /example/contact/edit/8
Traceback (most recent call last):
  File "C:\djangomerlin\lib\site-packages\django\core\handlers\base.py", line 115, in get_response
    response = callback(request, *callback_args, **callback_kwargs)
  File "C:\sessionwiz_models\example\views.py", line 185, in edit_wizard
    return form(context=RequestContext(request), request=request)
  File "C:\djangomerlin\lib\site-packages\django\views\generic\base.py", line 68, in view
    return self.dispatch(request, *args, **kwargs)
  File "C:\djangomerlin\lib\site-packages\django\contrib\formtools\wizard\views.py", line 227, in dispatch
    response = super(WizardView, self).dispatch(request, *args, **kwargs)
  File "C:\djangomerlin\lib\site-packages\django\views\generic\base.py", line 86, in dispatch
    return handler(request, *args, **kwargs)
  File "C:\sessionwiz_models\example\views.py", line 159, in post
    done_response = self.done(final_forms.values(), form_dict=final_forms, **kwargs)
  File "C:\sessionwiz_models\example\views.py", line 91, in done
    for field, value in form.cleaned_data.iteritems():
AttributeError: 'dict' object has no attribute 'cleaned_data'
2014-06-25 01:32:42,433 [ERROR] django.request: Internal Server Error: /example/contact/edit/8
Traceback (most recent call last):
  File "C:\djangomerlin\lib\site-packages\django\core\handlers\base.py", line 92, in get_response
    response = middleware_method(request)
  File "C:\djangomerlin\lib\site-packages\django\middleware\common.py", line 69, in process_request
    if (not urlresolvers.is_valid_path(request.path_info, urlconf) and
  File "C:\djangomerlin\lib\site-packages\django\core\urlresolvers.py", line 551, in is_valid_path
    resolve(path, urlconf)
  File "C:\djangomerlin\lib\site-packages\django\core\urlresolvers.py", line 440, in resolve
    return get_resolver(urlconf).resolve(path)
  File "C:\djangomerlin\lib\site-packages\django\core\urlresolvers.py", line 319, in resolve
    for pattern in self.url_patterns:
  File "C:\djangomerlin\lib\site-packages\django\core\urlresolvers.py", line 347, in url_patterns
    patterns = getattr(self.urlconf_module, "urlpatterns", self.urlconf_module)
  File "C:\djangomerlin\lib\site-packages\django\core\urlresolvers.py", line 342, in urlconf_module
    self._urlconf_module = import_module(self.urlconf_name)
  File "C:\djangomerlin\lib\site-packages\django\utils\importlib.py", line 35, in import_module
    __import__(name)
  File "C:\sessionwiz_models\sessionwiz\urls.py", line 8, in <module>
    url(r'^example/', include('example.urls', namespace='example')),
  File "C:\djangomerlin\lib\site-packages\django\conf\urls\__init__.py", line 25, in include
    urlconf_module = import_module(urlconf_module)
  File "C:\djangomerlin\lib\site-packages\django\utils\importlib.py", line 35, in import_module
    __import__(name)
  File "C:\sessionwiz_models\example\urls.py", line 5, in <module>
    from example import views
  File "C:\sessionwiz_models\example\views.py", line 91
    if form not None:
                   ^
SyntaxError: invalid syntax
2014-06-25 01:34:54,131 [ERROR] django.request: Internal Server Error: /example/contact/edit/8
Traceback (most recent call last):
  File "C:\djangomerlin\lib\site-packages\django\core\handlers\base.py", line 115, in get_response
    response = callback(request, *callback_args, **callback_kwargs)
  File "C:\sessionwiz_models\example\views.py", line 186, in edit_wizard
    return form(context=RequestContext(request), request=request)
  File "C:\djangomerlin\lib\site-packages\django\views\generic\base.py", line 68, in view
    return self.dispatch(request, *args, **kwargs)
  File "C:\djangomerlin\lib\site-packages\django\contrib\formtools\wizard\views.py", line 227, in dispatch
    response = super(WizardView, self).dispatch(request, *args, **kwargs)
  File "C:\djangomerlin\lib\site-packages\django\views\generic\base.py", line 86, in dispatch
    return handler(request, *args, **kwargs)
  File "C:\sessionwiz_models\example\views.py", line 160, in post
    done_response = self.done(final_forms.values(), form_dict=final_forms, **kwargs)
  File "C:\sessionwiz_models\example\views.py", line 92, in done
    for field, value in form.cleaned_data.iteritems():
AttributeError: 'dict' object has no attribute 'cleaned_data'
2014-06-25 01:37:53,960 [ERROR] django.request: Internal Server Error: /example/contact/edit/8
Traceback (most recent call last):
  File "C:\djangomerlin\lib\site-packages\django\core\handlers\base.py", line 115, in get_response
    response = callback(request, *callback_args, **callback_kwargs)
  File "C:\sessionwiz_models\example\views.py", line 186, in edit_wizard
    return form(context=RequestContext(request), request=request)
  File "C:\djangomerlin\lib\site-packages\django\views\generic\base.py", line 68, in view
    return self.dispatch(request, *args, **kwargs)
  File "C:\djangomerlin\lib\site-packages\django\contrib\formtools\wizard\views.py", line 227, in dispatch
    response = super(WizardView, self).dispatch(request, *args, **kwargs)
  File "C:\djangomerlin\lib\site-packages\django\views\generic\base.py", line 86, in dispatch
    return handler(request, *args, **kwargs)
  File "C:\sessionwiz_models\example\views.py", line 160, in post
    done_response = self.done(final_forms.values(), form_dict=final_forms, **kwargs)
  File "C:\sessionwiz_models\example\views.py", line 92, in done
    for field, value in form:
ValueError: too many values to unpack
2014-06-25 01:38:05,851 [ERROR] django.request: Internal Server Error: /example/contact/edit/8
Traceback (most recent call last):
  File "C:\djangomerlin\lib\site-packages\django\core\handlers\base.py", line 115, in get_response
    response = callback(request, *callback_args, **callback_kwargs)
  File "C:\sessionwiz_models\example\views.py", line 186, in edit_wizard
    return form(context=RequestContext(request), request=request)
  File "C:\djangomerlin\lib\site-packages\django\views\generic\base.py", line 68, in view
    return self.dispatch(request, *args, **kwargs)
  File "C:\djangomerlin\lib\site-packages\django\contrib\formtools\wizard\views.py", line 227, in dispatch
    response = super(WizardView, self).dispatch(request, *args, **kwargs)
  File "C:\djangomerlin\lib\site-packages\django\views\generic\base.py", line 86, in dispatch
    return handler(request, *args, **kwargs)
  File "C:\sessionwiz_models\example\views.py", line 160, in post
    done_response = self.done(final_forms.values(), form_dict=final_forms, **kwargs)
  File "C:\sessionwiz_models\example\views.py", line 100, in done
    form_data = [form.cleaned_data for form in form_list]
AttributeError: 'dict' object has no attribute 'cleaned_data'
2014-06-25 01:45:55,400 [ERROR] django.request: Internal Server Error: /example/contact/add/
Traceback (most recent call last):
  File "C:\djangomerlin\lib\site-packages\django\core\handlers\base.py", line 115, in get_response
    response = callback(request, *callback_args, **callback_kwargs)
  File "C:\djangomerlin\lib\site-packages\django\views\generic\base.py", line 68, in view
    return self.dispatch(request, *args, **kwargs)
  File "C:\djangomerlin\lib\site-packages\django\contrib\formtools\wizard\views.py", line 227, in dispatch
    response = super(WizardView, self).dispatch(request, *args, **kwargs)
  File "C:\djangomerlin\lib\site-packages\django\views\generic\base.py", line 86, in dispatch
    return handler(request, *args, **kwargs)
  File "C:\sessionwiz_models\example\views.py", line 167, in post
    return super(ContactWizard, self).post(self, *args, **kwargs)
  File "C:\djangomerlin\lib\site-packages\django\contrib\formtools\wizard\views.py", line 290, in post
    return self.render_done(form, **kwargs)
  File "C:\djangomerlin\lib\site-packages\django\contrib\formtools\wizard\views.py", line 332, in render_done
    done_response = self.done(final_form_list, **kwargs)
  File "C:\sessionwiz_models\example\views.py", line 97, in done
    setattr(instance, field, values)
NameError: global name 'values' is not defined
